Traceback (most recent call last):
  File "/home/allan/miniconda3/envs/reaktoro-jupyter-book/lib/python3.9/site-packages/jupyter_cache/executors/utils.py", line 51, in single_nb_execution
    executenb(
  File "/home/allan/miniconda3/envs/reaktoro-jupyter-book/lib/python3.9/site-packages/nbclient/client.py", line 1117, in execute
    return NotebookClient(nb=nb, resources=resources, km=km, **kwargs).execute()
  File "/home/allan/miniconda3/envs/reaktoro-jupyter-book/lib/python3.9/site-packages/nbclient/util.py", line 78, in wrapped
    return just_run(coro(*args, **kwargs))
  File "/home/allan/miniconda3/envs/reaktoro-jupyter-book/lib/python3.9/site-packages/nbclient/util.py", line 57, in just_run
    return loop.run_until_complete(coro)
  File "/home/allan/miniconda3/envs/reaktoro-jupyter-book/lib/python3.9/asyncio/base_events.py", line 642, in run_until_complete
    return future.result()
  File "/home/allan/miniconda3/envs/reaktoro-jupyter-book/lib/python3.9/site-packages/nbclient/client.py", line 558, in async_execute
    await self.async_execute_cell(
  File "/home/allan/miniconda3/envs/reaktoro-jupyter-book/lib/python3.9/site-packages/nbclient/client.py", line 862, in async_execute_cell
    self._check_raise_for_error(cell, exec_reply)
  File "/home/allan/miniconda3/envs/reaktoro-jupyter-book/lib/python3.9/site-packages/nbclient/client.py", line 765, in _check_raise_for_error
    raise CellExecutionError.from_cell_and_msg(cell, exec_reply_content)
nbclient.exceptions.CellExecutionError: An error occurred while executing the following cell:
------------------
brine = Material(system)
brine.add("H2O"  , 1.00, "kg")
brine.add("NaCl" , 1.00, "mol")
brine.add("CaCl2", 0.10, "mol")
brine.add("MgCl2", 0.05, "mol")
brine.add("CO2"  , 0.10, "mol")

rock = Material(system)
rock.set("SiO2",  80.0, "g")
rock.set("CaCO3", 20.0, "g")

mix = brine(1.0, "kg") + rock(10.0, "g")

state = mix.equilibrate(60, "celsius", 15, "bar")

------------------

[0;31m---------------------------------------------------------------------------[0m
[0;31mAttributeError[0m                            Traceback (most recent call last)
[0;32m/tmp/ipykernel_30901/267067165.py[0m in [0;36m<module>[0;34m[0m
[1;32m      7[0m [0;34m[0m[0m
[1;32m      8[0m [0mrock[0m [0;34m=[0m [0mMaterial[0m[0;34m([0m[0msystem[0m[0;34m)[0m[0;34m[0m[0;34m[0m[0m
[0;32m----> 9[0;31m [0mrock[0m[0;34m.[0m[0mset[0m[0;34m([0m[0;34m"SiO2"[0m[0;34m,[0m  [0;36m80.0[0m[0;34m,[0m [0;34m"g"[0m[0;34m)[0m[0;34m[0m[0;34m[0m[0m
[0m[1;32m     10[0m [0mrock[0m[0;34m.[0m[0mset[0m[0;34m([0m[0;34m"CaCO3"[0m[0;34m,[0m [0;36m20.0[0m[0;34m,[0m [0;34m"g"[0m[0;34m)[0m[0;34m[0m[0;34m[0m[0m
[1;32m     11[0m [0;34m[0m[0m

[0;31mAttributeError[0m: 'reaktoro.reaktoro4py.Material' object has no attribute 'set'
AttributeError: 'reaktoro.reaktoro4py.Material' object has no attribute 'set'

