Traceback (most recent call last):
  File "/home/allan/miniconda3/envs/reaktoro-jupyter-book/lib/python3.9/site-packages/jupyter_cache/executors/utils.py", line 51, in single_nb_execution
    executenb(
  File "/home/allan/miniconda3/envs/reaktoro-jupyter-book/lib/python3.9/site-packages/nbclient/client.py", line 1117, in execute
    return NotebookClient(nb=nb, resources=resources, km=km, **kwargs).execute()
  File "/home/allan/miniconda3/envs/reaktoro-jupyter-book/lib/python3.9/site-packages/nbclient/util.py", line 78, in wrapped
    return just_run(coro(*args, **kwargs))
  File "/home/allan/miniconda3/envs/reaktoro-jupyter-book/lib/python3.9/site-packages/nbclient/util.py", line 57, in just_run
    return loop.run_until_complete(coro)
  File "/home/allan/miniconda3/envs/reaktoro-jupyter-book/lib/python3.9/asyncio/base_events.py", line 642, in run_until_complete
    return future.result()
  File "/home/allan/miniconda3/envs/reaktoro-jupyter-book/lib/python3.9/site-packages/nbclient/client.py", line 558, in async_execute
    await self.async_execute_cell(
  File "/home/allan/miniconda3/envs/reaktoro-jupyter-book/lib/python3.9/site-packages/nbclient/client.py", line 862, in async_execute_cell
    self._check_raise_for_error(cell, exec_reply)
  File "/home/allan/miniconda3/envs/reaktoro-jupyter-book/lib/python3.9/site-packages/nbclient/client.py", line 765, in _check_raise_for_error
    raise CellExecutionError.from_cell_and_msg(cell, exec_reply_content)
nbclient.exceptions.CellExecutionError: An error occurred while executing the following cell:
------------------
state0 = ChemicalState(system)
state0.temperature(25.0, "celsius")
state0.pressure(1.0, "bar")
state0.set("CH4", 1.0, "mol")
state0.set("O2",  0.5, "mol")

props0 = ChemicalProps(state0)

V0 = props0.volume()  # the initial volume of the gases
U0 = props0.internalEnergy()  # the initial internal energy of the gases
------------------

[0;31m---------------------------------------------------------------------------[0m
[0;31mRuntimeError[0m                              Traceback (most recent call last)
[0;32m/tmp/ipykernel_9874/2886579036.py[0m in [0;36m<module>[0;34m[0m
[1;32m      2[0m [0mstate0[0m[0;34m.[0m[0mtemperature[0m[0;34m([0m[0;36m25.0[0m[0;34m,[0m [0;34m"celsius"[0m[0;34m)[0m[0;34m[0m[0;34m[0m[0m
[1;32m      3[0m [0mstate0[0m[0;34m.[0m[0mpressure[0m[0;34m([0m[0;36m1.0[0m[0;34m,[0m [0;34m"bar"[0m[0;34m)[0m[0;34m[0m[0;34m[0m[0m
[0;32m----> 4[0;31m [0mstate0[0m[0;34m.[0m[0mset[0m[0;34m([0m[0;34m"CH4"[0m[0;34m,[0m [0;36m1.0[0m[0;34m,[0m [0;34m"mol"[0m[0;34m)[0m[0;34m[0m[0;34m[0m[0m
[0m[1;32m      5[0m [0mstate0[0m[0;34m.[0m[0mset[0m[0;34m([0m[0;34m"O2"[0m[0;34m,[0m  [0;36m0.5[0m[0;34m,[0m [0;34m"mol"[0m[0;34m)[0m[0;34m[0m[0;34m[0m[0m
[1;32m      6[0m [0;34m[0m[0m

[0;31mRuntimeError[0m: [1;31m***ERROR*** Could not find any Species object with name CH4.
[0m
RuntimeError: [1;31m***ERROR*** Could not find any Species object with name CH4.
[0m

